Workbook

Sheet Painel
G32: Outputs:
G33: a) Perfil Setorial: predomínio do Terceiro Setor (65%), seguido pelo Privado (20%) e Público (11%), indicando um ecossistema movido por filantropia e cooperação técnica. b) Natureza das Organizações: presença de Grantmakers e Think Tanks, sinalizando alta capacidade de financiamento e formulação de estratégias. c) Eixo Temático Central: O nexo "Land, Food and Forest" é a prioridade em +60% do mapa. d) Influência Secundária: Building & Transport emergem como áreas de suporte para a descarbonização das cadeias produtivas. e) Alcance Geográfico: 74% possuem atuação Nacional, com 18% de conexões Internacionais. f) Lente Territorial: a Amazônia é o bioma prioritário absoluto, seguido pelo Cerrado e Mata Atlântica; biomas como Pampa e Caatinga aparecem de forma periférica.

Sheet Stakeholder list
B2: Stakeholder Ecosystem Mapping
B4: Project: Strategic ecosystem pre-assessment and stakeholders`mapping in Brazil
B5: Last update: 11/02/2026
B6: ID | C6: Stakeholder | D6: Organization's sector | E6: Type of organization | F6: Description of organization & contribution to systemic transition (strategic focus) | G6: Territorial focus (national, region, city) | H6: Primary impact area (sector of interest / Nexuses) | I6: Primary Territory lens (Biome) | J6: Secondary Territory lens (Biome) | K6: Biome focus rationale (only when the organization has explicit project/action targeting by biome) | L6: Role within the ecosystem | M6: Position in the value chain | N6: Potential partnership with IKF | O6: Headquarters location | P6: Funding Role | Q6: Contact (name, role and e-mail) | R6: Site / related links | S6: General notes / Refs | T6: MEL type / approach
B7: 1 | C7: Instituto Ibirapitanga | D7: Civil Society Organization (CSO) | E7: Philanthropy foundations | F7: A grantmaking organization that supports organizations, movements, and collectives to drive structural transformations, with a focus on democracy/civic freedoms, racial equity, and agendas such as fair and sustainable food systems. | G7: National | H7: "Land, Food and Forest" | I7: Amazonia | K7: Grantmaking is organized by themes such as democracy, racial equity and fair food systems, not by ecological territories. Funding can reach many regions, but biome targeting is not used as an allocation rule. | L7: Funder, Strategic partner | M7: Midstream | N7: Co-funding partner | O7: Rio de Janeiro, RJ, Brazil | P7: Donor | Q7: André Degenszajn (Executive Director) | R7: https://ibirapitanga.org.br/ | S7: Could be a relevant partner for co-funding efforts on food systems in the Amazon. | T7: —
B8: 2 | C8: Instituto Serrapilheira | D8: Civil Society Organization (CSO) | E8: Philanthropy foundations | F8: A private, non-profit philanthropic institute that promotes science in Brazil; it funds research, training, and journalism/media initiatives to strengthen evidence-based public and private decision-making. | G8: National | H8: "Land, Food and Forest" | K8: Portfolio follows scientific fields, fellowships and science communication priorities. Projects may occur in different places, yet the institute does not manage programs using biomes as the operating unit. | L8: Funder, Technical assistance / research, Strategic partner | M8: Midstream | N8: Co-funding partner | O8: Rio de Janeiro, RJ, Brazil | P8: Donor | Q8: Hugo Aguilaniu (President) | R8: https://serrapilheira.org/ | S8: Could be a relevant partner for co-funding efforts on science-based approaches, advocacy and communications | T8: —
B9: 3 | C9: Fundo Brasileiro para a Biodiversidade (FUNBIO) | D9: Civil Society Organization (CSO) | E9: Philanthropy foundations | F9: A national, private, non-profit financial mechanism that mobilizes and manages resources for biodiversity conservation, supporting initiatives, projects, and financing arrangements in partnership with government, the private sector, and civil society. | G9: National | H9: "Land, Food and Forest" | I9: Amazonia, Caatinga, Cerrado | J9: Mata&Atlântica, Pantanal, Pampa, Coastal&maritime | K9: Multi biome financial mechanism with recurring biodiversity pipelines in Amazonia and Cerrado. Other biomes appear through specific funds and projects, but with lower frequency in the core flow of managed initiatives. | L9: Funder, Capital provider / Financial intermediary | M9: Midstream | N9: Co-funding partner | O9: Rio de Janeiro, RJ, Brazil | P9: Re-granter | Q9: Rosa Lemos de Sá (Executive Director) | R9: https://www.funbio.org.br/ | S9: Potential co-funding, strategic partner & regranter to work in all Brazilan Biomes, with trackrecord as a financial mechanism to work on bioodiversituy, climate change and civil society stregnthening in all regions with a diverisity of national and international partenrs | T9: —
B10: 4 | C10: Instituto Clima e Sociedade (iCS) | D10: Civil Society Organization (CSO) | E10: Monitoring, Evaluation, and Learning | F10: A regranter organization that supports tackling climate change by funding agendas and actors capable of accelerating a just and effective transition to a low-carbon economy. | G10: National | H10: Buildings & Transport, Energy, "Land, Food and Forest" | I10: Amazonia, Caatinga, Cerrado | J10: Mata&Atlântica, Pantanal, Pampa, Coastal&maritime | K10: Grantmaking frequently connects climate and land use priorities in Amazonia, Cerrado and Caatinga. Additional biomes are supported through partners and calls, but are not the main recurring anchors of the portfolio. | L10: Funder, Strategic partner, Convenor/enablers, Capital provider / Financial intermediary | M10: Upstream | N10: Strategic partner | O10: Rio de Janeiro, RJ, Brazil | P10: Re-granter | Q10: Maria Netto Schnider | R10: https://climaesociedade.org/ | S10: Regrenter organization well posionetd in Brazil in different arenas to address climate change issues | T10: Portfolio impact monitoring & strategic evaluation of climate programs and climate finance
B11: 5 | C11: Instituto Cultura, Comunicação e Incidência (ICCI) | D11: Civil Society Organization (CSO) | E11: Philanthropy foundations | F11: A non-profit regranting organization focused on strengthening strategic communication to advance climate, democracy, and justice agendas, creating social demand for public policy and impactful private action. | G11: National | H11: Buildings & Transport, Energy, "Land, Food and Forest" | K11: Work is centered on strategic communication and policy influence rather than place based delivery. Campaign geography varies by agenda, so no stable biome delimitation is consistently observable. | L11: Project developer / Implementer, Policy influence / regulation | M11: Midstream | N11: Grant recipient | O11: Rio de Janeiro, RJ, Brazil | P11: Re-granter | Q11: Marco Kelson Kertzman | R11: https://www.iccibr.org/en/home | S11: A new player with great potential to advance climate change communication strategies in Brazil. | T11: —
B12: 6 | C12: Grupo de Institutos, Fundações e Empresas (GIFE) | D12: Civil Society Organization (CSO) | E12: Multi-stakeholder initiatives | F12: An association/platform within Brazil’s philanthropy and private social investment ecosystem; it convenes a network, produces knowledge, and strengthens institutional capacities for strategic and coordinated action. | G12: National | H12: Buildings & Transport, Energy, "Land, Food and Forest" | K12: Acts as a philanthropy platform focused on standards, learning and capacity building. Its territorial reach depends on members and partners, making biome classification non essential for its operating model. | L12: Convenor/enablers | M12: Upstream | N12: Strategic partner | O12: São Paulo, SP, Brazil | P12: Grantee | Q12: Carolla Matarazzo (Chairman) | R12: https://gife.org.br/ | S12: The most relevant network of Philanthropies in Brazil. Could be a strategic partner to address IKF workin Brazil. | T12: —
B13: 7 | C13: Movimento Bem Maior (MBM) | D13: Civil Society Organization (CSO) | E13: Alliances | F13: A philanthropic movement/network that connects donors, organizations, and partners for systemic transformation, promoting a culture of giving, active citizenship, and the strengthening of the third sector, specially philanthropies in Brazil. | G13: National | H13: Buildings & Transport, "Land, Food and Forest" | I13: Amazonia | K13: Network to mobilize giving and strengthen civil society across Brazil. Territorial footprint is partner driven and campaign driven, without a consistent program design structured by biome boundaries. | L13: Funder, Convenor/enablers | M13: Upstream | N13: Co-funding partner | O13: São Paulo, SP, Brazil | P13: Donor | Q13: Carolla Matarazzo (Executive Director) | R13: https://movimentobemmaior.org.br/ | S13: A Philanthropy established 5 years ago by 9 business leaders to enhance the grant making space in Brazil. Looking foward to co-finance strategies with other philanthropies (national and international). Could be a strategic partner for IKF in Brazil. | T13: —
B14: 8 | C14: Instituto Beija | D14: Civil Society Organization (CSO) | E14: Alliances | F14: a social impact organization that promotes a positive impact in the philanthropic ecosystem by fostering creativity, innovation, and collaboration, together with the engagement of civil society, the private sector and the government to solve systemic problems | G14: National | H14: Buildings & Transport, Energy, "Land, Food and Forest", Emergency response | K14: NA | L14: Funder, Convenor/enablers | M14: Upstream | N14: Co-funding partner | O14: Rio de Janeiro, RJ, Brazil | P14: Donor | Q14: Cristiane Sultani (Funder and Chairman) | R14: https://institutobeja.org/homepage/ | S14: A recently established Philantropy, with a similar role of Movoimento Bem Maior, to advance the givin culture in Brazil. Could be a relevant co-funder and strategic partner for IKF in Brazil. | T14: —
B15: 9 | C15: Open Society Foundations | D15: Funders | E15: Philanthropy foundations | F15: A global grantmaking philanthropic foundation focused on rights, equity, justice, democracy, and human rights; it supports organizations and initiatives in multiple countries with a focus on structural change. | G15: Cross-border / international | H15: Buildings & Transport, Emergency response, Energy, "Land, Food and Forest" | I15: Amazonia | K15: Global rights and democracy funder with broad country portfolios. In this mapping, Brazil support is not publicly organized in a way that allows a consistent biome based segmentation, but has a mention about impact in Amazon region. | L15: Funder, Strategic partner | M15: Upstream | N15: Co-funding partner | O15: New York, NY, USA | P15: Donor | Q15: Pedro Abramovay (Vice-President) | R15: https://www.opensocietyfoundations.org/newsroom/a-open-society-na-america-latina-e-no-caribe/pt | S15: They have a strong presence in Brazil. Could be a strategic partner, specially to give inputs on strategy development, approaches and lessosn learned. | T15: —
B16: 10 | C16: Instituto Ethos | D16: Civil Society Organization (CSO) | E16: Industry platforms and sectoral initiatives | F16: A civil society organization network that mobilizes and supports companies toward socially responsible and sustainable management; it develops tools, indicators, and convening efforts to strengthen socio-environmental integrity and influence policy. | G16: National | H16: Buildings & Transport, Energy, "Land, Food and Forest" | I16: Amazonia | J16: Mata&Atlântica, Pantanal, Pampa, Coastal&maritime | K16: Corporate integrity and sustainability work often engages high deforestation risk supply chains, making Amazonia the most recurrent reference. National advocacy and tools also apply beyond Amazonia, but not as a biome specific portfolio. | L16: Convenor/enablers, Policy influence / regulation | M16: Upstream | N16: Strategic partner | O16: São Paulo, SP, Brazil | P16: Grantee | Q16: Caio Magri (President) | R16: https://www.ethos.org.br/ | S16: Together with GIFE (Philantropy network), Ethos was stablished in Brazil as strong network to address social corporate responsability in the 90's. Would be interesting to talk to them to test their apetite to collaborate with IKF Impact Areas strategies. | T16: —
B17: 11 | C17: Instituto para o Desenvolvimento do Investimento Social (IDIS) | D17: Civil Society Organization (CSO) | E17: Think tanks | F17: A civil society organization that inspires, supports, and expands private social investment and its impact; it works through consulting/strategy, knowledge production, and strengthening the philanthropic ecosystem. | G17: National | H17: Buildings & Transport, Energy, "Land, Food and Forest" | K17: Operates as a philanthropy and social investment advisor and ecosystem builder. Workstreams are instrument and strategy based, so biome delimitation is not a meaningful organizing lens. | L17: Technical assistance / research, Convenor/enablers | M17: Upstream | N17: Grant recipient | O17: São Paulo, SP, Brazil | P17: Grantee | Q17: Paula Jancso Fabiani | R17: https://www.idis.org.br/ | S17: Provide services to develop civil society organizations in Brazil. Hosts and endowment fund to develop Philantropies in Brazil. | T17: —
B18: 12 | C18: Instituto Climate Ventures Brasil (Climate Ventures) | D18: Civil Society Organization (CSO) | E18: Think tanks | F18: A think-and-do tank that coordinates multi-stakeholder action and produces knowledge for systemic climate solutions; it connects actors (business, government, finance, and civil society) to accelerate a just transition and climate innovation. | G18: National | H18: Buildings & Transport, Energy, "Land, Food and Forest" | I18: Amazonia, Caatinga, Cerrado | J18: Mata&Atlântica, Pantanal, Pampa, Coastal&maritime | K18: Coordinates climate solutions with strong land use and regional transition interfaces, often most salient in Amazonia, Cerrado and Caatinga. Other biomes enter through specific coalitions, not as the primary recurring focus. | L18: Convenor/enablers, Project developer / Implementer | M18: Midstream | N18: Grant recipient | O18: São Paulo, SP, Brazil | P18: Grantee | Q18: Daniel Contrucci & Ricardo Gravnina (Co-Directors) | R18: https://www.climateventures.co/ | S18: Could be an important grantee in the cosytem to address climate solutions in Brazil. | T18: —
B19: 13 | C19: The Climate Group | D19: Civil Society Organization (CSO) | E19: Multi-stakeholder initiatives | F19: An international non-profit organization that runs corporate initiatives and coalitions (e.g., in energy/transport/industry) to accelerate net-zero targets, acting as a secretariat for alliances and mobilizing sectoral commitments. | G19: Cross-border / international | H19: Buildings & Transport, Energy | K19: Runs global corporate coalitions and sector commitments. Brazil engagement is typically framed by companies and policies, not by territorially delimited biome programs. | L19: Convenor/enablers, Strategic partner | M19: Upstream | N19: Grant recipient | O19: London, United Kingdom | P19: Grantee | Q19: Champa Patel (Global Governance Director) | R19: https://www.theclimategroup.org/ | S19: Potential partner. Intrested in working more in Brazil. | T19: —
B20: 14 | C20: Fundação Maria Cecilia Souto Vidigal | D20: Funders | E20: Philanthropy foundations | F20: A civil society organization focused on early childhood; it mobilizes leaders, supports governments and public policy, and produces evidence to reduce inequalities from the very beginning of life. | G20: National | K20: Focuses on early childhood evidence and public policy adoption by states and municipalities. Implementation geography is administrative and service based, not ecosystem based. | L20: Funder, Strategic partner | M20: Upstream | N20: Co-funding partner | O20: São Paulo, SP, Brazil | P20: Donor | Q20: Mariana Luz (Executive Director) | R20: https://fundacaomariacecilia.org.br/ | S20: Explore possibilities to be a partner. The largest endowment fund in Brazil. | T20: —
B21: 15 | C21: Fundação Tide Setúbal | D21: Funders | E21: Philanthropy foundations | F21: A foundation focused on social justice and the sustainable development of urban peripheries; it fosters initiatives and connects the state, research, and civil society to tackle socio-spatial inequalities and influence policy. | G21: National | J21: Mata&Atlântica | K21: Prioritizes urban peripheries and socio spatial inequality agendas. The operating territory is metropolitan and social, so biomes are not used to define programs. | L21: Funder, Territorial anchor | M21: Upstream | N21: Co-funding partner | O21: São Paulo, SP, Brazil | P21: Donor | Q21: Mariana Almeida (Executive Director) | R21: https://fundacaotidesetubal.org.br/ | S21: Could be a co-funding partener in urban startegies in targeted cities (as SP), supporting vulnerable comunities. | T21: —
B22: 16 | C22: Fundação Arymax | D22: Funders | E22: Philanthropy foundations | F22: A philanthropic foundation (venture philanthropy) focused on productive inclusion, employability, and organizational strengthening; it supports scalable solutions and a culture of evaluation/effectiveness to expand social impact. | G22: National | H22: Emergency response, "Land, Food and Forest" | K22: Venture philanthropy for employability and productive inclusion, oriented to scalable solutions and organizational strengthening. No consistent biome targeting appears in how programs are selected or reported. | L22: Funder, Strategic partner | M22: Upstream | N22: Co-funding partner | O22: São Paulo, SP, Brazil | P22: Donor | Q22: Viviane Naigeborin (Executive Director) | R22: https://arymax.org.br/ | S22: Potential co-funding partner in Social Impact Business (SIB) in Brazil. The org. Lead helped establishing policies and frameworks and is a reference on SIB in Brazil. | T22: —
B23: 17 | C23: Instituto Talanoa | D23: Civil Society Organization (CSO) | E23: Monitoring, Evaluation, and Learning | F23: An independent think tank dedicated to climate policy in Brazil; it combines data, science, and dialogue to monitor, analyze, and influence public policy and climate governance, increasing transparency and decision quality. | G23: National | H23: Buildings & Transport, Energy, "Land, Food and Forest" | I23: Amazonia, Caatinga, Cerrado | J23: Mata&Atlântica, Pantanal, Pampa, Coastal&maritime | K23: Produces climate governance analysis where Amazonia and Cerrado repeatedly dominate national debates on land use and NDC ambition. Other biomes are covered in broader policy discussion rather than dedicated biome programs. | L23: Technical assistance / research, Policy influence / regulation | M23: Midstream | N23: Strategic partner | O23: Brasília, DF, Brazil | P23: Grantee | Q23: Natalie Unterstell | R23: https://institutotalanoa.org/ | S23: A relevant thecnical partner in Brazil (policy, adaptation and mitigation) | T23: Climate policy monitoring, data-driven analysis and transparency of climate governance
B24: 18 | C24: Instituto Alana | D24: Civil Society Organization (CSO) | E24: Philanthropy foundations | F24: A civil society organization focused on the rights of children and adolescents; it works through advocacy, communication, and partnerships to ensure priority for childhood and promote integral development with socio-environmental justice. | G24: National | H24: "Land, Food and Forest" | I24: Amazonia, Caatinga, Cerrado | J24: Mata&Atlântica | K24: Works on children and adolescent rights with advocacy and communication strategies. Actions are not designed around biome defined geographies. | L24: Funder, Policy influence / regulation, Strategic partner , Community legitimacy / proximate leadership | M24: Midstream | N24: Co-funding partner | O24: São Paulo, SP, Brazil | P24: Donor | Q24: Ana Lúcia Villela (President) & Marcos Nisti (Vice-President) | R24: https://alana.org.br/ | S24: Could be a co-finding partner on targeted audience. Works a lot in advocacy, campaigns and information foucesed on young generation) | T24: —
B25: 19 | C25: Itaúsa (Itaúsa S.A.) | D25: Private sector | E25: Institutional Investors | F25: A publicly listed holding company; it invests in a portfolio of companies and can influence the transition through governance, ESG strategy, capital allocation, and engagement for sustainable development and positive impact. | G25: National | H25: Buildings & Transport, Energy, "Land, Food and Forest" | K25: Influence is exercised through portfolio governance, ESG and capital allocation. No public strategy indicates biome specific territorial programming. | L25: Strategic partner, Capital provider / Financial intermediary | M25: Upstream | N25: Co-funding partner | O25: São Paulo, SP, Brazil | P25: Re-granter | Q25: Marcelo Furtado (Sustainable Head) | R25: https://www.itausa.com.br/ | S25: Interested in the climate change. Alredy finance a lot of different effort, hubs and networks. Could be a co-funding partner for IKF in Brazil. | T25: —
B26: 20 | C26: Instituto Arapyaú | D26: Civil Society Organization (CSO) | E26: Philanthropy foundations | F26: A Brazilian philanthropic organization that fosters and incubates networks and structuring initiatives to promote fair, inclusive, and low-carbon development; it convenes public/private actors and civil society to advance systemic solutions in climate, nature, and the economy. | G26: National | H26: Buildings & Transport, Energy, "Land, Food and Forest" | I26: Amazonia | J26: Mata&Atlântica | K26: Sustained territorial convening and networks are most visibly linked to Amazonia, with additional recurring work connected to Mata Atlântica agendas. The biome tagging reflects where long term coalitions and place based initiatives concentrate. | L26: Funder, Strategic partner, Territorial anchor | M26: Midstream | N26: Co-funding partner | O26: São Paulo, SP, Brazil | P26: Donor | Q26: Renata Piazzon (CEO) | R26: https://arapyau.org.br/ | S26: Relevant partner to co-fund initiatives in teh Amazon. Also works a lot in terrritorial development in Bahia. Guilherme Leal's philanthropy (one of Natura's owner) | T26: —
B27: 21 | C27: Instituto Semeia | D27: Civil Society Organization (CSO) | E27: Philanthropy foundations | F27: A non-profit philanthropic organization focused on enhancing the sustainable socioeconomic development of parks and protected areas, supporting management models, partnerships, and knowledge for conservation and visitation. | G27: National | H27: "Land, Food and Forest" | I27: Amazonia, Cerrado | J27: Mata&Atlântica, Pantanal, Pampa, Coastal&maritime | K27: Parks and protected areas agenda spans multiple regions, with recurring relevance in Amazonia and Cerrado due to scale and pressure dynamics. Other biomes appear through specific protected area partnerships and knowledge products. | L27: Technical assistance / research, Project developer / Implementer, Funder | M27: Midstream | N27: Co-funding partner | O27: São Paulo, SP, Brazil | P27: Donor | Q27: Fernando Pieroni (Executive Director) | R27: https://semeia.org.br/ | S27: Interesting partner to understand and potentially co-fund strategies to address Public and Private Prtnerships (PPPs) in IKF impact areas. Perdo Passos' philanthropy (one of Natura's owner). | T27: —
B28: 22 | C28: The David and Lucile Packard Foundation | D28: Funders | E28: Philanthropy foundations | F28: An international grantmaking philanthropic foundation that funds agendas such as conservation/restoration of natural systems, climate, and community strengthening; it supports organizations and coalitions for structural, evidence-based change. | G28: Cross-border / international | H28: Energy, "Land, Food and Forest" | K28: International grantmaker with broad environment and community portfolios. This list does not provide a stable Brazil facing biome structured program line to classify. | L28: Funder, Strategic partner | M28: Upstream | N28: Co-funding partner | O28: Los Altos, CA, USA | P28: Donor | R28: https://www.packard.org/ | S28: Potential partner in Brazil. Explore a range of sustainable territorial development approaches and lessons lerned funding initiatives in Brazil. | T28: —
B29: 23 | C29: Alcoa | D29: Private sector | E29: Private companies (large / leading) | F29: A global company in the aluminum sector (bauxite, alumina, and aluminum); it contributes to the transition through industrial decarbonization, ESG standards, traceability, and engagement with supply chains and the territories where it operates. | G29: Cross-border / international | H29: Buildings & Transport, Energy | I29: Amazonia | J29: Coastal&maritime | K29: Operational footprint and risk management are most consistently associated with Amazonia. Coastal maritime appears as a secondary interface through logistics and export corridors rather than a dedicated conservation program. | L29: Strategic partner, Implementation capacity (delivery) | M29: Downstream | N29: Co-funding partner | O29: Pittsburgh, PA, USA | P29: Donor | R29: https://www.alcoa.com/brasil/pt | S29: Could be a potential co-funding partner in targeted geographies, linkes to IKF impact areas. | T29: —
B30: 24 | C30: Norsk Hydro ASA (Hydro) | D30: Private sector | E30: Private companies (large / leading) | F30: A global leader in aluminum and renewable energy; it can drive the transition through circular economy practices, emissions reductions, materials innovation, socio-environmental governance, and investment in low-carbon value chains. | G30: Cross-border / international | H30: Buildings & Transport, Energy | I30: Amazonia | J30: Coastal&maritime | K30: Industrial and mining assets create a strong linkage to Amazonia. Coastal maritime is included as a secondary lens due to transport and port logistics interfaces that shape impacts and mitigation needs. | L30: Strategic partner, Implementation capacity (delivery) | M30: Midstream | N30: Co-funding partner | O30: Oslo, Norway | P30: Donor | R30: https://www.hydro.com/br | S30: Could be a potential co-funding partner in targeted geographies, linkes to IKF impact areas. | T30: —
B31: 25 | C31: Instituto Socioambiental (ISA) | D31: Civil Society Organization (CSO) | E31: Local implementers | F31: A Brazilian NGO (OSCIP) that defends the rights and territories of Indigenous Peoples and traditional communities and protects socio-environmental heritage; it contributes through advocacy, monitoring, and integrated solutions for conservation and socio-environmental justice. | G31: National | H31: "Land, Food and Forest" | I31: Amazonia | J31: Mata&Atlântica | K31: Long running rights and territorial governance work is strongly anchored in Amazonia. A secondary linkage to Mata Atlântica reflects additional initiatives and advocacy connected to that biome domain. | L31: Project developer / Implementer, Community legitimacy / proximate leadership | M31: Midstream | N31: Implementing partner | O31: São Paulo, SP, Brazil | P31: Grantee | Q31: Adriana Ramos (Policy Director) | T31: —
B32: 26 | C32: The Nature Conservancy Brasil (TNC Brasil) | D32: Civil Society Organization (CSO) | E32: Local implementers | F32: A science-based international conservation NGO; it develops local solutions to protect land and water, restore ecosystems, and design financing/arrangements for conservation, connecting the public and private sectors and communities. | G32: Cross-border / international | H32: "Land, Food and Forest" | I32: Amazonia, Cerrado | J32: Mata&Atlântica, Coastal&maritime | K32: Territorial programs and partnerships are most robust in Amazonia and Cerrado. Mata Atlântica and Coastal maritime appear through complementary water, restoration and coastal linked initiatives. | L32: Strategic partner, Project developer / Implementer | M32: Upstream | N32: Grant recipient | O32: Arlington, VA, USA | P32: Grantee | T32: —
B33: 27 | C33: Conservação Internacional Brasil (CI-Brasil) | D33: Civil Society Organization (CSO) | E33: Local implementers | F33: A conservation NGO that works with nature-based solutions, science, and partnerships to protect biodiversity and promote human well-being; it operates through field projects, policy work, and coalitions. | G33: Cross-border / international | H33: "Land, Food and Forest" | I33: Amazonia, Cerrado | J33: Mata&Atlântica, Coastal&maritime | K33: Multi biome conservation portfolio with recurring emphasis on Amazonia and Cerrado. Mata Atlântica and Coastal maritime show up through specific projects and themes rather than being the main program anchors. | L33: Strategic partner, Project developer / Implementer | M33: Upstream | N33: Grant recipient | O33: Arlington, VA, USA | P33: Grantee | T33: —
B34: 28 | C34: WWF-Brasil | D34: Civil Society Organization (CSO) | E34: Local implementers | F34: A Brazilian NGO dedicated to conserving life and promoting a future in which society and nature live in harmony; it contributes through advocacy, projects, social mobilization, and influence on supply chains and public policy. | G34: Cross-border / international | H34: "Land, Food and Forest" | I34: Amazonia, Cerrado | J34: Pantanal, Mata&Atlântica | K34: High visibility campaigns and projects frequently center on Amazonia and Cerrado. Pantanal and Mata Atlântica remain relevant through water, biodiversity and climate risk agendas in a secondary layer. | L34: Strategic partner, Project developer / Implementer, Policy influence / regulation | M34: Midstream | N34: Grant recipient | O34: Brasília, DF, Brazil | P34: Grantee | T34: —
B35: 29 | C35: WRI Brasil | D35: Civil Society Organization (CSO) | E35: Monitoring, Evaluation, and Learning | F35: A non-profit applied research and convening institution that turns evidence into action on climate, forests, cities, and land use; it supports public policy, planning, and implementation of low-carbon solutions through multi-stakeholder partnerships. | G35: Cross-border / international | H35: Buildings & Transport, Energy, "Land, Food and Forest" | I35: Amazonia, Caatinga, Cerrado | J35: Mata&Atlântica | K35: Evidence to action work often focuses on land use and transition challenges most salient in Amazonia, Cerrado and Caatinga. Mata Atlântica appears through cities, infrastructure and policy work that intersects that biome footprint. | L35: Strategic partner, Technical assistance / research, Policy influence / regulation | M35: Upstream | N35: Grant recipient | O35: São Paulo, SP, Brazil | P35: Grantee | T35: Evidence-based research, data platforms and evaluation of climate and land-use policies
B36: 30 | C36: Fundação SOS Mata Atlântica | D36: Funders | E36: Monitoring, Evaluation, and Learning | F36: A Brazilian environmental NGO whose mission is to inspire society to defend the Atlantic Forest; it works through monitoring, studies, demonstration projects, communication, and advocacy in public policy and territorial governance. | G36: National | H36: "Land, Food and Forest" | J36: Mata&Atlântica | K36: Mission, monitoring and advocacy are explicitly dedicated to Mata Atlântica. This single biome focus is consistent across programs and public positioning. | L36: Policy influence / regulation, Implementation capacity (delivery) | M36: Midstream | N36: Grant recipient | O36: São Paulo, SP, Brazil | P36: Grantee | T36: Environmental monitoring of Atlantic Forest; deforestation tracking and advocacy indicators
B37: 31 | C37: Empresa Brasileira de Pesquisa Agropecuária (Embrapa) | D37: Public sector | E37: Research centers | F37: A federal public company for agricultural R&D; it contributes to systemic transition through innovation and technology diffusion for sustainable agriculture, climate adaptation, productivity, and reduced environmental impacts. | G37: National | H37: "Land, Food and Forest" | I37: Amazonia, Caatinga, Cerrado | J37: Mata&Atlântica, Pantanal, Pampa, Coastal&maritime | K37: National agricultural research network with core innovation and adaptation agendas strongly present in Cerrado, Caatinga and Amazonia. Other biomes are covered institutionally but are less central in the most recurrent transition narratives. | L37: Technical assistance / research, Territorial anchor | M37: Upstream | N37: Strategic partner | O37: Brasília, DF, Brazil | P37: Grantee | T37: —
B38: 32 | C38: Sistema S | D38: Others | E38: Industry platforms and sectoral initiatives | F38: A set of entities providing vocational training and public-interest services (e.g., SENAI, SESI, SESC, SENAC, etc.) financed through sectoral contributions; it contributes to the transition through training, reskilling, and innovation for work and productivity in strategic sectors. | G38: National | H38: Buildings & Transport, Energy | K38: Delivery model is based on training networks, sectoral services and local units. Programs are not defined by biomes, so biome tagging is not operationally meaningful. | L38: Implementation capacity (delivery), Technical assistance / research | M38: Midstream | N38: Strategic partner | O38: Brasília, DF, Brazil | P38: Grantee | T38: —
B39: 33 | C39: Instituto Brasileiro do Meio Ambiente e dos Recursos Naturais Renováveis (Ibama) | D39: Public sector | E39: Public agencies and regulators | F39: A federal agency responsible for environmental enforcement and control; it contributes to systemic transition through regulation, licensing, monitoring, combating environmental crimes, and inducing socio-environmental compliance. | G39: National | H39: Energy, "Land, Food and Forest" | I39: Amazonia, Caatinga, Cerrado | J39: Mata&Atlântica, Pantanal, Pampa, Coastal&maritime | K39: National enforcement and licensing mandate covers all biomes, but pressure hotspots make Amazonia, Cerrado and Caatinga the most recurrent references. Remaining biomes are still within scope, yet not a distinctive program delimitation. | L39: Policy influence / regulation, Territorial anchor | M39: Upstream | N39: Strategic partner | O39: Brasília, DF, Brazil | P39: Grantee | T39: —
B40: 34 | C40: Instituto Chico Mendes de Conservação da Biodiversidade (ICMBio) | D40: Public sector | E40: Public agencies and regulators | F40: A federal agency responsible for managing and overseeing federal protected areas; it contributes through biodiversity protection, restoration, protected-area management, and implementation of conservation policies. | G40: National | H40: "Land, Food and Forest" | I40: Amazonia, Caatinga, Cerrado | J40: Mata&Atlântica, Pantanal, Pampa, Coastal&maritime | K40: Manages federal protected areas across all biomes by mandate. The primary tags reflect where protected area scale and conflict pressures are most pronounced, while other biomes remain part of nationwide coverage. | L40: Policy influence / regulation, Territorial anchor | M40: Upstream | N40: Strategic partner | O40: Brasília, DF, Brazil | P40: Grantee | T40: —
B41: 35 | C41: Instituto do Homem e Meio Ambiente da Amazônia (Imazon) | D41: Civil Society Organization (CSO) | E41: Monitoring, Evaluation, and Learning | F41: A non-profit scientific institution that produces research and solutions for forest conservation and socio-environmental development in the Amazon; it works with data, monitoring, policy evaluation, and projects. | G41: Regional | H41: "Land, Food and Forest" | I41: Amazonia | K41: Research and monitoring are explicitly focused on Amazonia forest dynamics and governance. There is no recurring second biome portfolio line in the institute core work. | L41: Technical assistance / research, Data / MRV / platforms | M41: Upstream | N41: Grant recipient | O41: Belém, PA, Brazil | P41: Grantee | T41: Amazon deforestation monitoring, MRV data systems and policy evaluation (PRODES/SAD)
B42: 36 | C42: Fundação Amazonas Sustentável (FAS) | D42: Funders | E42: Local implementers | F42: A non-profit civil society organization working for sustainable development in the Amazon through community programs and multi-stakeholder partnerships; it contributes to the transition through conservation combined with productive inclusion and territorial strengthening. | G42: State-level | H42: "Land, Food and Forest" | I42: Amazonia | K42: Community based conservation and livelihoods programs are designed for Amazonia territories. Territorial focus is stable and central to the operating model. | L42: Project developer / Implementer, Territorial anchor | M42: Midstream | N42: Grant recipient | O42: Manaus, AM, Brazil | P42: Grantee | T42: —
...

Sheet Data_Looker
A1: ='Stakeholder list'!B6 | B1: ='Stakeholder list'!C6 | C1: ='Stakeholder list'!D6 | D1: ='Stakeholder list'!E6 | E1: ='Stakeholder list'!F6 | F1: ='Stakeholder list'!G6 | G1: ='Stakeholder list'!H6 | H1: ='Stakeholder list'!I6 | ... R1: ='Stakeholder list'!S6
A2: ='Stakeholder list'!B7 | B2: ='Stakeholder list'!C7 | C2: ='Stakeholder list'!D7 | D2: ='Stakeholder list'!E7 | E2: ='Stakeholder list'!F7 | F2: ='Stakeholder list'!G7 | G2: ='Stakeholder list'!H7 | H2: ='Stakeholder list'!I7 | ... R2: ='Stakeholder list'!S7
A3: ='Stakeholder list'!B8 | B3: ='Stakeholder list'!C8 | C3: ='Stakeholder list'!D8 | D3: ='Stakeholder list'!E8 | E3: ='Stakeholder list'!F8 | F3: ='Stakeholder list'!G8 | G3: ='Stakeholder list'!H8 | H3: ='Stakeholder list'!I8 | ... R3: ='Stakeholder list'!S8
A4: ='Stakeholder list'!B9 | B4: ='Stakeholder list'!C9 | C4: ='Stakeholder list'!D9 | D4: ='Stakeholder list'!E9 | E4: ='Stakeholder list'!F9 | F4: ='Stakeholder list'!G9 | G4: ='Stakeholder list'!H9 | H4: ='Stakeholder list'!I9 | ... R4: ='Stakeholder list'!S9
A5: ='Stakeholder list'!B10 | B5: ='Stakeholder list'!C10 | C5: ='Stakeholder list'!D10 | D5: ='Stakeholder list'!E10 | E5: ='Stakeholder list'!F10 | F5: ='Stakeholder list'!G10 | G5: ='Stakeholder list'!H10 | H5: ='Stakeholder list'!I10 | ... R5: ='Stakeholder list'!S10
A6: ='Stakeholder list'!B11 | B6: ='Stakeholder list'!C11 | C6: ='Stakeholder list'!D11 | D6: ='Stakeholder list'!E11 | E6: ='Stakeholder list'!F11 | F6: ='Stakeholder list'!G11 | G6: ='Stakeholder list'!H11 | H6: ='Stakeholder list'!I11 | ... R6: ='Stakeholder list'!S11
A7: ='Stakeholder list'!B12 | B7: ='Stakeholder list'!C12 | C7: ='Stakeholder list'!D12 | D7: ='Stakeholder list'!E12 | E7: ='Stakeholder list'!F12 | F7: ='Stakeholder list'!G12 | G7: ='Stakeholder list'!H12 | H7: ='Stakeholder list'!I12 | ... R7: ='Stakeholder list'!S12
A8: ='Stakeholder list'!B13 | B8: ='Stakeholder list'!C13 | C8: ='Stakeholder list'!D13 | D8: ='Stakeholder list'!E13 | E8: ='Stakeholder list'!F13 | F8: ='Stakeholder list'!G13 | G8: ='Stakeholder list'!H13 | H8: ='Stakeholder list'!I13 | ... R8: ='Stakeholder list'!S13
A9: ='Stakeholder list'!B14 | B9: ='Stakeholder list'!C14 | C9: ='Stakeholder list'!D14 | D9: ='Stakeholder list'!E14 | E9: ='Stakeholder list'!F14 | F9: ='Stakeholder list'!G14 | G9: ='Stakeholder list'!H14 | H9: ='Stakeholder list'!I14 | ... R9: ='Stakeholder list'!S14
A10: ='Stakeholder list'!B15 | B10: ='Stakeholder list'!C15 | C10: ='Stakeholder list'!D15 | D10: ='Stakeholder list'!E15 | E10: ='Stakeholder list'!F15 | F10: ='Stakeholder list'!G15 | G10: ='Stakeholder list'!H15 | H10: ='Stakeholder list'!I15 | ... R10: ='Stakeholder list'!S15
A11: ='Stakeholder list'!B16 | B11: ='Stakeholder list'!C16 | C11: ='Stakeholder list'!D16 | D11: ='Stakeholder list'!E16 | E11: ='Stakeholder list'!F16 | F11: ='Stakeholder list'!G16 | G11: ='Stakeholder list'!H16 | H11: ='Stakeholder list'!I16 | ... R11: ='Stakeholder list'!S16
A12: ='Stakeholder list'!B17 | B12: ='Stakeholder list'!C17 | C12: ='Stakeholder list'!D17 | D12: ='Stakeholder list'!E17 | E12: ='Stakeholder list'!F17 | F12: ='Stakeholder list'!G17 | G12: ='Stakeholder list'!H17 | H12: ='Stakeholder list'!I17 | ... R12: ='Stakeholder list'!S17
... A14: ='Stakeholder list'!B19 | B14: ='Stakeholder list'!C19 | C14: ='Stakeholder list'!D19 | D14: ='Stakeholder list'!E19 | E14: ='Stakeholder list'!F19 | F14: ='Stakeholder list'!G19 | G14: ='Stakeholder list'!H19 | H14: ='Stakeholder list'!I19 | ... R14: ='Stakeholder list'!S19
A15: ='Stakeholder list'!B20 | B15: ='Stakeholder list'!C20 | C15: ='Stakeholder list'!D20 | D15: ='Stakeholder list'!E20 | E15: ='Stakeholder list'!F20 | F15: ='Stakeholder list'!G20 | G15: ='Stakeholder list'!H20 | H15: ='Stakeholder list'!I20 | ... W15: ='Stakeholder list'!X20
A16: ='Stakeholder list'!B21 | B16: ='Stakeholder list'!C21 | C16: ='Stakeholder list'!D21 | D16: ='Stakeholder list'!E21 | E16: ='Stakeholder list'!F21 | F16: ='Stakeholder list'!G21 | G16: ='Stakeholder list'!H21 | H16: ='Stakeholder list'!I21 | ... W16: ='Stakeholder list'!X21
A17: ='Stakeholder list'!B22 | B17: ='Stakeholder list'!C22 | C17: ='Stakeholder list'!D22 | D17: ='Stakeholder list'!E22 | E17: ='Stakeholder list'!F22 | F17: ='Stakeholder list'!G22 | G17: ='Stakeholder list'!H22 | H17: ='Stakeholder list'!I22 | ... W17: ='Stakeholder list'!X22
A18: ='Stakeholder list'!B23 | B18: ='Stakeholder list'!C23 | C18: ='Stakeholder list'!D23 | D18: ='Stakeholder list'!E23 | E18: ='Stakeholder list'!F23 | F18: ='Stakeholder list'!G23 | G18: ='Stakeholder list'!H23 | H18: ='Stakeholder list'!I23 | ... W18: ='Stakeholder list'!X23
A19: ='Stakeholder list'!B24 | B19: ='Stakeholder list'!C24 | C19: ='Stakeholder list'!D24 | D19: ='Stakeholder list'!E24 | E19: ='Stakeholder list'!F24 | F19: ='Stakeholder list'!G24 | G19: ='Stakeholder list'!H24 | H19: ='Stakeholder list'!I24 | ... W19: ='Stakeholder list'!X24
A20: ='Stakeholder list'!B25 | B20: ='Stakeholder list'!C25 | C20: ='Stakeholder list'!D25 | D20: ='Stakeholder list'!E25 | E20: ='Stakeholder list'!F25 | F20: ='Stakeholder list'!G25 | G20: ='Stakeholder list'!H25 | H20: ='Stakeholder list'!I25 | ... W20: ='Stakeholder list'!X25
A21: ='Stakeholder list'!B26 | B21: ='Stakeholder list'!C26 | C21: ='Stakeholder list'!D26 | D21: ='Stakeholder list'!E26 | E21: ='Stakeholder list'!F26 | F21: ='Stakeholder list'!G26 | G21: ='Stakeholder list'!H26 | H21: ='Stakeholder list'!I26 | ... W21: ='Stakeholder list'!X26
A22: ='Stakeholder list'!B27 | B22: ='Stakeholder list'!C27 | C22: ='Stakeholder list'!D27 | D22: ='Stakeholder list'!E27 | E22: ='Stakeholder list'!F27 | F22: ='Stakeholder list'!G27 | G22: ='Stakeholder list'!H27 | H22: ='Stakeholder list'!I27 | ... W22: ='Stakeholder list'!X27
A23: ='Stakeholder list'!B28 | B23: ='Stakeholder list'!C28 | C23: ='Stakeholder list'!D28 | D23: ='Stakeholder list'!E28 | E23: ='Stakeholder list'!F28 | F23: ='Stakeholder list'!G28 | G23: ='Stakeholder list'!H28 | H23: ='Stakeholder list'!I28 | ... W23: ='Stakeholder list'!X28
A24: ='Stakeholder list'!B29 | B24: ='Stakeholder list'!C29 | C24: ='Stakeholder list'!D29 | D24: ='Stakeholder list'!E29 | E24: ='Stakeholder list'!F29 | F24: ='Stakeholder list'!G29 | G24: ='Stakeholder list'!H29 | H24: ='Stakeholder list'!I29 | ... W24: ='Stakeholder list'!X29
A25: ='Stakeholder list'!B30 | B25: ='Stakeholder list'!C30 | C25: ='Stakeholder list'!D30 | D25: ='Stakeholder list'!E30 | E25: ='Stakeholder list'!F30 | F25: ='Stakeholder list'!G30 | G25: ='Stakeholder list'!H30 | H25: ='Stakeholder list'!I30 | ... W25: ='Stakeholder list'!X30
A26: ='Stakeholder list'!B31 | B26: ='Stakeholder list'!C31 | C26: ='Stakeholder list'!D31 | D26: ='Stakeholder list'!E31 | E26: ='Stakeholder list'!F31 | F26: ='Stakeholder list'!G31 | G26: ='Stakeholder list'!H31 | H26: ='Stakeholder list'!I31 | ... W26: ='Stakeholder list'!X31
... A361: ='Stakeholder list'!B366 | B361: ='Stakeholder list'!C366 | C361: ='Stakeholder list'!D366 | D361: ='Stakeholder list'!E366 | E361: ='Stakeholder list'!F366 | F361: ='Stakeholder list'!G366 | G361: ='Stakeholder list'!H366 | H361: ='Stakeholder list'!I366 | ... W361: ='Stakeholder list'!X366
A362: ='Stakeholder list'!B368 | B362: ='Stakeholder list'!C368 | C362: ='Stakeholder list'!D368 | D362: ='Stakeholder list'!E368 | E362: ='Stakeholder list'!F368 | F362: ='Stakeholder list'!G368 | G362: ='Stakeholder list'!H368 | H362: ='Stakeholder list'!I368 | ... R362: ='Stakeholder list'!S368
A363: ='Stakeholder list'!B369 | B363: ='Stakeholder list'!C369 | C363: ='Stakeholder list'!D369 | D363: ='Stakeholder list'!E369 | E363: ='Stakeholder list'!F369 | F363: ='Stakeholder list'!G369 | G363: ='Stakeholder list'!H369 | H363: ='Stakeholder list'!I369 | ... R363: ='Stakeholder list'!S369
A364: ='Stakeholder list'!B370 | B364: ='Stakeholder list'!C370 | C364: ='Stakeholder list'!D370 | D364: ='Stakeholder list'!E370 | E364: ='Stakeholder list'!F370 | F364: ='Stakeholder list'!G370 | G364: ='Stakeholder list'!H370 | H364: ='Stakeholder list'!I370 | ... R364: ='Stakeholder list'!S370
A365: ='Stakeholder list'!B371 | B365: ='Stakeholder list'!C371 | C365: ='Stakeholder list'!D371 | D365: ='Stakeholder list'!E371 | E365: ='Stakeholder list'!F371 | F365: ='Stakeholder list'!G371 | G365: ='Stakeholder list'!H371 | H365: ='Stakeholder list'!I371 | ... R365: ='Stakeholder list'!S371
A366: ='Stakeholder list'!B372 | B366: ='Stakeholder list'!C372 | C366: ='Stakeholder list'!D372 | D366: ='Stakeholder list'!E372 | E366: ='Stakeholder list'!F372 | F366: ='Stakeholder list'!G372 | G366: ='Stakeholder list'!H372 | H366: ='Stakeholder list'!I372 | ... R366: ='Stakeholder list'!S372
A367: ='Stakeholder list'!B373 | B367: ='Stakeholder list'!C373 | C367: ='Stakeholder list'!D373 | D367: ='Stakeholder list'!E373 | E367: ='Stakeholder list'!F373 | F367: ='Stakeholder list'!G373 | G367: ='Stakeholder list'!H373 | H367: ='Stakeholder list'!I373 | ... R367: ='Stakeholder list'!S373
A368: ='Stakeholder list'!B374 | B368: ='Stakeholder list'!C374 | C368: ='Stakeholder list'!D374 | D368: ='Stakeholder list'!E374 | E368: ='Stakeholder list'!F374 | F368: ='Stakeholder list'!G374 | G368: ='Stakeholder list'!H374
A369: ='Stakeholder list'!B375 | B369: ='Stakeholder list'!C375 | C369: ='Stakeholder list'!D375 | D369: ='Stakeholder list'!E375 | E369: ='Stakeholder list'!F375 | F369: ='Stakeholder list'!G375 | G369: ='Stakeholder list'!H375

Sheet Página11
A1: Stakeholder | B1: Type of organization
A2: Instituto Alana | B2: Think tanks
A3: Instituto Socioambiental (ISA) | B3: Local implementers
A4: The Nature Conservancy Brasil (TNC Brasil) | B4: Local implementers
A5: Conservação Internacional Brasil (CI-Brasil) | B5: Local implementers
A6: WWF-Brasil | B6: Local implementers
A7: Fundação SOS Mata Atlântica | B7: Local implementers
A8: Fundação Amazonas Sustentável (FAS) | B8: Local implementers
A9: Instituto de Manejo e Certificação Florestal e Agrícola (Imaflora) | B9: Local implementers
A10: Instituto de Conservação e Desenvolvimento Sustentável da Amazônia (IDESAM) | B10: Local implementers
A11: Artemisia | B11: Local implementers
A12: Instituto Conexões Sustentáveis (Conexsus) | B12: Local implementers
... A42: Visão Mundial (Visão Mundial) | B42: Local implementers

Sheet Bridge_Primary_Impact_Area
A1: =IFERROR(__xludf.DUMMYFUNCTION("ARRAYFORMULA(QUERY(SUBSTITUTE(SPLIT(FLATTEN(Data_Looker!B1:B339 & ""|"" & SPLIT(SUBSTITUTE(Data_Looker!G1:G339, ""Land, Food and Forest"", ""PROTEGER1""), "", "", FALSE)), ""|""), ""PROTEGER1"", ""Land, Food and Forest""), ""where Col2 <> ''""))"),"Stakeholder ") | B1: =IFERROR(__xludf.DUMMYFUNCTION("""COMPUTED_VALUE"""),"Primary impact area (sector of interest / Nexuses)")
A2: =IFERROR(__xludf.DUMMYFUNCTION("""COMPUTED_VALUE"""),"Instituto Ibirapitanga") | B2: =IFERROR(__xludf.DUMMYFUNCTION("""COMPUTED_VALUE"""),"""Land, Food and Forest""")
A3: =IFERROR(__xludf.DUMMYFUNCTION("""COMPUTED_VALUE"""),"Instituto Serrapilheira") | B3: =IFERROR(__xludf.DUMMYFUNCTION("""COMPUTED_VALUE"""),"""Land, Food and Forest""")
A4: =IFERROR(__xludf.DUMMYFUNCTION("""COMPUTED_VALUE"""),"Fundo Brasileiro para a Biodiversidade (FUNBIO)") | B4: =IFERROR(__xludf.DUMMYFUNCTION("""COMPUTED_VALUE"""),"""Land, Food and Forest""")
A5: =IFERROR(__xludf.DUMMYFUNCTION("""COMPUTED_VALUE"""),"Instituto Clima e Sociedade (iCS)") | B5: =IFERROR(__xludf.DUMMYFUNCTION("""COMPUTED_VALUE"""),"Buildings & Transport")
A6: =IFERROR(__xludf.DUMMYFUNCTION("""COMPUTED_VALUE"""),"Instituto Clima e Sociedade (iCS)") | B6: =IFERROR(__xludf.DUMMYFUNCTION("""COMPUTED_VALUE"""),"Energy")
A7: =IFERROR(__xludf.DUMMYFUNCTION("""COMPUTED_VALUE"""),"Instituto Clima e Sociedade (iCS)") | B7: =IFERROR(__xludf.DUMMYFUNCTION("""COMPUTED_VALUE"""),"""Land, Food and Forest""")
A8: =IFERROR(__xludf.DUMMYFUNCTION("""COMPUTED_VALUE"""),"Instituto Cultura, Comunicação e Incidência (ICCI)") | B8: =IFERROR(__xludf.DUMMYFUNCTION("""COMPUTED_VALUE"""),"Buildings & Transport")
A9: =IFERROR(__xludf.DUMMYFUNCTION("""COMPUTED_VALUE"""),"Instituto Cultura, Comunicação e Incidência (ICCI)") | B9: =IFERROR(__xludf.DUMMYFUNCTION("""COMPUTED_VALUE"""),"Energy")
A10: =IFERROR(__xludf.DUMMYFUNCTION("""COMPUTED_VALUE"""),"Instituto Cultura, Comunicação e Incidência (ICCI)") | B10: =IFERROR(__xludf.DUMMYFUNCTION("""COMPUTED_VALUE"""),"""Land, Food and Forest""")
A11: =IFERROR(__xludf.DUMMYFUNCTION("""COMPUTED_VALUE"""),"Grupo de Institutos, Fundações e Empresas (GIFE)") | B11: =IFERROR(__xludf.DUMMYFUNCTION("""COMPUTED_VALUE"""),"Buildings & Transport")
A12: =IFERROR(__xludf.DUMMYFUNCTION("""COMPUTED_VALUE"""),"Grupo de Institutos, Fundações e Empresas (GIFE)") | B12: =IFERROR(__xludf.DUMMYFUNCTION("""COMPUTED_VALUE"""),"Energy")
A13: =IFERROR(__xludf.DUMMYFUNCTION("""COMPUTED_VALUE"""),"Grupo de Institutos, Fundações e Empresas (GIFE)") | B13: =IFERROR(__xludf.DUMMYFUNCTION("""COMPUTED_VALUE"""),"""Land, Food and Forest""")
A14: =IFERROR(__xludf.DUMMYFUNCTION("""COMPUTED_VALUE"""),"Movimento Bem Maior (MBM)") | B14: =IFERROR(__xludf.DUMMYFUNCTION("""COMPUTED_VALUE"""),"Buildings & Transport")
A15: =IFERROR(__xludf.DUMMYFUNCTION("""COMPUTED_VALUE"""),"Movimento Bem Maior (MBM)") | B15: =IFERROR(__xludf.DUMMYFUNCTION("""COMPUTED_VALUE"""),"""Land, Food and Forest""")
A16: =IFERROR(__xludf.DUMMYFUNCTION("""COMPUTED_VALUE"""),"Instituto Beija ") | B16: =IFERROR(__xludf.DUMMYFUNCTION("""COMPUTED_VALUE"""),"Buildings & Transport")
A17: =IFERROR(__xludf.DUMMYFUNCTION("""COMPUTED_VALUE"""),"Instituto Beija ") | B17: =IFERROR(__xludf.DUMMYFUNCTION("""COMPUTED_VALUE"""),"Energy")
A18: =IFERROR(__xludf.DUMMYFUNCTION("""COMPUTED_VALUE"""),"Instituto Beija ") | B18: =IFERROR(__xludf.DUMMYFUNCTION("""COMPUTED_VALUE"""),"""Land, Food and Forest""")
A19: =IFERROR(__xludf.DUMMYFUNCTION("""COMPUTED_VALUE"""),"Instituto Beija ") | B19: =IFERROR(__xludf.DUMMYFUNCTION("""COMPUTED_VALUE"""),"Emergency response")
A20: =IFERROR(__xludf.DUMMYFUNCTION("""COMPUTED_VALUE"""),"Open Society Foundations") | B20: =IFERROR(__xludf.DUMMYFUNCTION("""COMPUTED_VALUE"""),"Buildings & Transport")
A21: =IFERROR(__xludf.DUMMYFUNCTION("""COMPUTED_VALUE"""),"Open Society Foundations") | B21: =IFERROR(__xludf.DUMMYFUNCTION("""COMPUTED_VALUE"""),"Emergency response")
A22: =IFERROR(__xludf.DUMMYFUNCTION("""COMPUTED_VALUE"""),"Open Society Foundations") | B22: =IFERROR(__xludf.DUMMYFUNCTION("""COMPUTED_VALUE"""),"Energy")
A23: =IFERROR(__xludf.DUMMYFUNCTION("""COMPUTED_VALUE"""),"Open Society Foundations") | B23: =IFERROR(__xludf.DUMMYFUNCTION("""COMPUTED_VALUE"""),"""Land, Food and Forest""")
A24: =IFERROR(__xludf.DUMMYFUNCTION("""COMPUTED_VALUE"""),"Instituto Ethos") | B24: =IFERROR(__xludf.DUMMYFUNCTION("""COMPUTED_VALUE"""),"Buildings & Transport")
A25: =IFERROR(__xludf.DUMMYFUNCTION("""COMPUTED_VALUE"""),"Instituto Ethos") | B25: =IFERROR(__xludf.DUMMYFUNCTION("""COMPUTED_VALUE"""),"Energy")
A26: =IFERROR(__xludf.DUMMYFUNCTION("""COMPUTED_VALUE"""),"Instituto Ethos") | B26: =IFERROR(__xludf.DUMMYFUNCTION("""COMPUTED_VALUE"""),"""Land, Food and Forest""")
A27: =IFERROR(__xludf.DUMMYFUNCTION("""COMPUTED_VALUE"""),"Instituto para o Desenvolvimento do Investimento Social (IDIS)") | B27: =IFERROR(__xludf.DUMMYFUNCTION("""COMPUTED_VALUE"""),"Buildings & Transport")
A28: =IFERROR(__xludf.DUMMYFUNCTION("""COMPUTED_VALUE"""),"Instituto para o Desenvolvimento do Investimento Social (IDIS)") | B28: =IFERROR(__xludf.DUMMYFUNCTION("""COMPUTED_VALUE"""),"Energy")
A29: =IFERROR(__xludf.DUMMYFUNCTION("""COMPUTED_VALUE"""),"Instituto para o Desenvolvimento do Investimento Social (IDIS)") | B29: =IFERROR(__xludf.DUMMYFUNCTION("""COMPUTED_VALUE"""),"""Land, Food and Forest""")
A30: =IFERROR(__xludf.DUMMYFUNCTION("""COMPUTED_VALUE"""),"Instituto Climate Ventures Brasil (Climate Ventures)") | B30: =IFERROR(__xludf.DUMMYFUNCTION("""COMPUTED_VALUE"""),"Buildings & Transport")
A31: =IFERROR(__xludf.DUMMYFUNCTION("""COMPUTED_VALUE"""),"Instituto Climate Ventures Brasil (Climate Ventures)") | B31: =IFERROR(__xludf.DUMMYFUNCTION("""COMPUTED_VALUE"""),"Energy")
A32: =IFERROR(__xludf.DUMMYFUNCTION("""COMPUTED_VALUE"""),"Instituto Climate Ventures Brasil (Climate Ventures)") | B32: =IFERROR(__xludf.DUMMYFUNCTION("""COMPUTED_VALUE"""),"""Land, Food and Forest""")
A33: =IFERROR(__xludf.DUMMYFUNCTION("""COMPUTED_VALUE"""),"The Climate Group") | B33: =IFERROR(__xludf.DUMMYFUNCTION("""COMPUTED_VALUE"""),"Buildings & Transport")
A34: =IFERROR(__xludf.DUMMYFUNCTION("""COMPUTED_VALUE"""),"The Climate Group") | B34: =IFERROR(__xludf.DUMMYFUNCTION("""COMPUTED_VALUE"""),"Energy")
A35: =IFERROR(__xludf.DUMMYFUNCTION("""COMPUTED_VALUE"""),"Fundação Arymax") | B35: =IFERROR(__xludf.DUMMYFUNCTION("""COMPUTED_VALUE"""),"Emergency response")
A36: =IFERROR(__xludf.DUMMYFUNCTION("""COMPUTED_VALUE"""),"Fundação Arymax") | B36: =IFERROR(__xludf.DUMMYFUNCTION("""COMPUTED_VALUE"""),"""Land, Food and Forest""")
A37: =IFERROR(__xludf.DUMMYFUNCTION("""COMPUTED_VALUE"""),"Instituto Talanoa") | B37: =IFERROR(__xludf.DUMMYFUNCTION("""COMPUTED_VALUE"""),"Buildings & Transport")
A38: =IFERROR(__xludf.DUMMYFUNCTION("""COMPUTED_VALUE"""),"Instituto Talanoa") | B38: =IFERROR(__xludf.DUMMYFUNCTION("""COMPUTED_VALUE"""),"Energy")
A39: =IFERROR(__xludf.DUMMYFUNCTION("""COMPUTED_VALUE"""),"Instituto Talanoa") | B39: =IFERROR(__xludf.DUMMYFUNCTION("""COMPUTED_VALUE"""),"""Land, Food and Forest""")
A40: =IFERROR(__xludf.DUMMYFUNCTION("""COMPUTED_VALUE"""),"Instituto Alana") | B40: =IFERROR(__xludf.DUMMYFUNCTION("""COMPUTED_VALUE"""),"""Land, Food and Forest""")
...

Sheet Data_aluvial_Donnors
A1: Funding Role | B1: Primary impact area (sector of interest / Nexuses)
A2: Donor | B2: Land, Food and Forest
A3: Donor | B3: Land, Food and Forest
A4: Re-granter | B4: Land, Food and Forest
A5: Re-granter | B5: Buildings & Transport
A6: Re-granter | B6: Energy
A7: Re-granter | B7: Land, Food and Forest
A8: Re-granter | B8: Buildings & Transport
A9: Re-granter | B9: Energy
A10: Re-granter | B10: Land, Food and Forest
A11: Grantee | B11: Buildings & Transport
A12: Grantee | B12: Energy
... A550: Grantee | B550: Energy

Sheet Bridge_Primary_Biome
A1: Stakeholder | B1: Biome
A2: =IFERROR(__xludf.DUMMYFUNCTION("ARRAYFORMULA(QUERY(SPLIT(FLATTEN(Data_Looker!B2:B340 & ""|"" & SPLIT(Data_Looker!H2:H340, "", "")), ""|""), ""where Col2 <> ''""))"),"Instituto Ibirapitanga") | B2: =IFERROR(__xludf.DUMMYFUNCTION("""COMPUTED_VALUE"""),"Amazonia")
A3: =IFERROR(__xludf.DUMMYFUNCTION("""COMPUTED_VALUE"""),"Fundo Brasileiro para a Biodiversidade (FUNBIO)") | B3: =IFERROR(__xludf.DUMMYFUNCTION("""COMPUTED_VALUE"""),"Amazonia")
A4: =IFERROR(__xludf.DUMMYFUNCTION("""COMPUTED_VALUE"""),"Fundo Brasileiro para a Biodiversidade (FUNBIO)") | B4: =IFERROR(__xludf.DUMMYFUNCTION("""COMPUTED_VALUE"""),"Caatinga")
A5: =IFERROR(__xludf.DUMMYFUNCTION("""COMPUTED_VALUE"""),"Fundo Brasileiro para a Biodiversidade (FUNBIO)") | B5: =IFERROR(__xludf.DUMMYFUNCTION("""COMPUTED_VALUE"""),"Cerrado")
A6: =IFERROR(__xludf.DUMMYFUNCTION("""COMPUTED_VALUE"""),"Instituto Clima e Sociedade (iCS)") | B6: =IFERROR(__xludf.DUMMYFUNCTION("""COMPUTED_VALUE"""),"Amazonia")
A7: =IFERROR(__xludf.DUMMYFUNCTION("""COMPUTED_VALUE"""),"Instituto Clima e Sociedade (iCS)") | B7: =IFERROR(__xludf.DUMMYFUNCTION("""COMPUTED_VALUE"""),"Caatinga")
A8: =IFERROR(__xludf.DUMMYFUNCTION("""COMPUTED_VALUE"""),"Instituto Clima e Sociedade (iCS)") | B8: =IFERROR(__xludf.DUMMYFUNCTION("""COMPUTED_VALUE"""),"Cerrado")
A9: =IFERROR(__xludf.DUMMYFUNCTION("""COMPUTED_VALUE"""),"Movimento Bem Maior (MBM)") | B9: =IFERROR(__xludf.DUMMYFUNCTION("""COMPUTED_VALUE"""),"Amazonia")
A10: =IFERROR(__xludf.DUMMYFUNCTION("""COMPUTED_VALUE"""),"Open Society Foundations") | B10: =IFERROR(__xludf.DUMMYFUNCTION("""COMPUTED_VALUE"""),"Amazonia")
A11: =IFERROR(__xludf.DUMMYFUNCTION("""COMPUTED_VALUE"""),"Instituto Ethos") | B11: =IFERROR(__xludf.DUMMYFUNCTION("""COMPUTED_VALUE"""),"Amazonia")
A12: =IFERROR(__xludf.DUMMYFUNCTION("""COMPUTED_VALUE"""),"Instituto Climate Ventures Brasil (Climate Ventures)") | B12: =IFERROR(__xludf.DUMMYFUNCTION("""COMPUTED_VALUE"""),"Amazonia")
A13: =IFERROR(__xludf.DUMMYFUNCTION("""COMPUTED_VALUE"""),"Instituto Climate Ventures Brasil (Climate Ventures)") | B13: =IFERROR(__xludf.DUMMYFUNCTION("""COMPUTED_VALUE"""),"Caatinga")
A14: =IFERROR(__xludf.DUMMYFUNCTION("""COMPUTED_VALUE"""),"Instituto Climate Ventures Brasil (Climate Ventures)") | B14: =IFERROR(__xludf.DUMMYFUNCTION("""COMPUTED_VALUE"""),"Cerrado")
A15: =IFERROR(__xludf.DUMMYFUNCTION("""COMPUTED_VALUE"""),"Instituto Talanoa") | B15: =IFERROR(__xludf.DUMMYFUNCTION("""COMPUTED_VALUE"""),"Amazonia")
A16: =IFERROR(__xludf.DUMMYFUNCTION("""COMPUTED_VALUE"""),"Instituto Talanoa") | B16: =IFERROR(__xludf.DUMMYFUNCTION("""COMPUTED_VALUE"""),"Caatinga")
A17: =IFERROR(__xludf.DUMMYFUNCTION("""COMPUTED_VALUE"""),"Instituto Talanoa") | B17: =IFERROR(__xludf.DUMMYFUNCTION("""COMPUTED_VALUE"""),"Cerrado")
A18: =IFERROR(__xludf.DUMMYFUNCTION("""COMPUTED_VALUE"""),"Instituto Alana") | B18: =IFERROR(__xludf.DUMMYFUNCTION("""COMPUTED_VALUE"""),"Amazonia")
A19: =IFERROR(__xludf.DUMMYFUNCTION("""COMPUTED_VALUE"""),"Instituto Alana") | B19: =IFERROR(__xludf.DUMMYFUNCTION("""COMPUTED_VALUE"""),"Caatinga")
A20: =IFERROR(__xludf.DUMMYFUNCTION("""COMPUTED_VALUE"""),"Instituto Alana") | B20: =IFERROR(__xludf.DUMMYFUNCTION("""COMPUTED_VALUE"""),"Cerrado")
A21: =IFERROR(__xludf.DUMMYFUNCTION("""COMPUTED_VALUE"""),"Instituto Arapyaú") | B21: =IFERROR(__xludf.DUMMYFUNCTION("""COMPUTED_VALUE"""),"Amazonia")
A22: =IFERROR(__xludf.DUMMYFUNCTION("""COMPUTED_VALUE"""),"Instituto Semeia") | B22: =IFERROR(__xludf.DUMMYFUNCTION("""COMPUTED_VALUE"""),"Amazonia")
A23: =IFERROR(__xludf.DUMMYFUNCTION("""COMPUTED_VALUE"""),"Instituto Semeia") | B23: =IFERROR(__xludf.DUMMYFUNCTION("""COMPUTED_VALUE"""),"Cerrado")
A24: =IFERROR(__xludf.DUMMYFUNCTION("""COMPUTED_VALUE"""),"Alcoa") | B24: =IFERROR(__xludf.DUMMYFUNCTION("""COMPUTED_VALUE"""),"Amazonia")
A25: =IFERROR(__xludf.DUMMYFUNCTION("""COMPUTED_VALUE"""),"Norsk Hydro ASA (Hydro)") | B25: =IFERROR(__xludf.DUMMYFUNCTION("""COMPUTED_VALUE"""),"Amazonia")
A26: =IFERROR(__xludf.DUMMYFUNCTION("""COMPUTED_VALUE"""),"Instituto Socioambiental (ISA)") | B26: =IFERROR(__xludf.DUMMYFUNCTION("""COMPUTED_VALUE"""),"Amazonia")
A27: =IFERROR(__xludf.DUMMYFUNCTION("""COMPUTED_VALUE"""),"The Nature Conservancy Brasil (TNC Brasil)") | B27: =IFERROR(__xludf.DUMMYFUNCTION("""COMPUTED_VALUE"""),"Amazonia")
A28: =IFERROR(__xludf.DUMMYFUNCTION("""COMPUTED_VALUE"""),"The Nature Conservancy Brasil (TNC Brasil)") | B28: =IFERROR(__xludf.DUMMYFUNCTION("""COMPUTED_VALUE"""),"Cerrado")
A29: =IFERROR(__xludf.DUMMYFUNCTION("""COMPUTED_VALUE"""),"Conservação Internacional Brasil (CI-Brasil)") | B29: =IFERROR(__xludf.DUMMYFUNCTION("""COMPUTED_VALUE"""),"Amazonia")
A30: =IFERROR(__xludf.DUMMYFUNCTION("""COMPUTED_VALUE"""),"Conservação Internacional Brasil (CI-Brasil)") | B30: =IFERROR(__xludf.DUMMYFUNCTION("""COMPUTED_VALUE"""),"Cerrado")
A31: =IFERROR(__xludf.DUMMYFUNCTION("""COMPUTED_VALUE"""),"WWF-Brasil") | B31: =IFERROR(__xludf.DUMMYFUNCTION("""COMPUTED_VALUE"""),"Amazonia")
A32: =IFERROR(__xludf.DUMMYFUNCTION("""COMPUTED_VALUE"""),"WWF-Brasil") | B32: =IFERROR(__xludf.DUMMYFUNCTION("""COMPUTED_VALUE"""),"Cerrado")
A33: =IFERROR(__xludf.DUMMYFUNCTION("""COMPUTED_VALUE"""),"WRI Brasil") | B33: =IFERROR(__xludf.DUMMYFUNCTION("""COMPUTED_VALUE"""),"Amazonia")
